Workbook
Name detail1: 'Dataset-1'!$B$3:$L$612
Name Slicer_Days: #N/A
Name Slicer_Dteday: #N/A
Name Slicer_Temp: #N/A
Name Slicer_Time: #N/A
Name Slicer_Weather: #N/A

Sheet Dataset-1
A1: instant | B1: dteday | C1: season | D1: yr | E1: mnth | F1: hr | H1: holiday | I1: weekday | K1: weathersit | L1: temp
A2: =PROPER(A1) -> Instant | B2: =PROPER(B1) -> Dteday | C2: =PROPER(C1) -> Season | D2: =PROPER(D1) -> Yr | E2: =PROPER(E1) -> Mnth | F2: =PROPER(F1) -> Hr | G2: Time | H2: =PROPER(H1) -> Holiday | I2: =PROPER(I1) -> Weekday | J2: Days | K2: =PROPER(K1) -> Weathersit | L2: =PROPER(L1) -> Temp | M2: Weather
A3: 1 | B3: 40544 | C3: 1 | D3: 0 | E3: 1 | F3: 0 | G3: {=_xlfn.IFS(AND(F3>=5,F3<12),"Morning",AND(F3>=12,F3<17),"AfterNoon",AND(F3>=17,F3<20),"Evening",TRUE,"Night")} -> Night | H3: FALSE | I3: 6 | J3: {=_xlfn.IFS(I3=0,"Saturday",I3=1,"Sunday",I3=2,"Monday",I3=3,"Tuesday",I3=4,"Wednesday",I3=5,"Thusday",I3=6,"Friday")} -> Friday | K3: 1 | L3: 0.24 | M3: =IF(L3<=0.1,"Stromy",IF(L3<=0.2,"Rainy",IF(L3<=0.3,"Cloudy","Sunny"))) -> Cloudy
A4: 2 | B4: 40544 | C4: 1 | D4: 0 | E4: 1 | F4: 1 | G4: {=_xlfn.IFS(AND(F4>=5,F4<12),"Morning",AND(F4>=12,F4<17),"AfterNoon",AND(F4>=17,F4<20),"Evening",TRUE,"Night")} -> Night | H4: FALSE | I4: 6 | J4: {=_xlfn.IFS(I4=0,"Saturday",I4=1,"Sunday",I4=2,"Monday",I4=3,"Tuesday",I4=4,"Wednesday",I4=5,"Thusday",I4=6,"Friday")} -> Friday | K4: 1 | L4: 0.22 | M4: =IF(L4<=0.1,"Stromy",IF(L4<=0.2,"Rainy",IF(L4<=0.3,"Cloudy","Sunny"))) -> Cloudy
A5: 3 | B5: 40544 | C5: 1 | D5: 0 | E5: 1 | F5: 2 | G5: {=_xlfn.IFS(AND(F5>=5,F5<12),"Morning",AND(F5>=12,F5<17),"AfterNoon",AND(F5>=17,F5<20),"Evening",TRUE,"Night")} -> Night | H5: FALSE | I5: 6 | J5: {=_xlfn.IFS(I5=0,"Saturday",I5=1,"Sunday",I5=2,"Monday",I5=3,"Tuesday",I5=4,"Wednesday",I5=5,"Thusday",I5=6,"Friday")} -> Friday | K5: 1 | L5: 0.22 | M5: =IF(L5<=0.1,"Stromy",IF(L5<=0.2,"Rainy",IF(L5<=0.3,"Cloudy","Sunny"))) -> Cloudy
A6: 4 | B6: 40544 | C6: 1 | D6: 0 | E6: 1 | F6: 3 | G6: {=_xlfn.IFS(AND(F6>=5,F6<12),"Morning",AND(F6>=12,F6<17),"AfterNoon",AND(F6>=17,F6<20),"Evening",TRUE,"Night")} -> Night | H6: FALSE | I6: 6 | J6: {=_xlfn.IFS(I6=0,"Saturday",I6=1,"Sunday",I6=2,"Monday",I6=3,"Tuesday",I6=4,"Wednesday",I6=5,"Thusday",I6=6,"Friday")} -> Friday | K6: 1 | L6: 0.24 | M6: =IF(L6<=0.1,"Stromy",IF(L6<=0.2,"Rainy",IF(L6<=0.3,"Cloudy","Sunny"))) -> Cloudy
A7: 5 | B7: 40544 | C7: 1 | D7: 0 | E7: 1 | F7: 4 | G7: {=_xlfn.IFS(AND(F7>=5,F7<12),"Morning",AND(F7>=12,F7<17),"AfterNoon",AND(F7>=17,F7<20),"Evening",TRUE,"Night")} -> Night | H7: FALSE | I7: 6 | J7: {=_xlfn.IFS(I7=0,"Saturday",I7=1,"Sunday",I7=2,"Monday",I7=3,"Tuesday",I7=4,"Wednesday",I7=5,"Thusday",I7=6,"Friday")} -> Friday | K7: 1 | L7: 0.24 | M7: =IF(L7<=0.1,"Stromy",IF(L7<=0.2,"Rainy",IF(L7<=0.3,"Cloudy","Sunny"))) -> Cloudy
A8: 6 | B8: 40544 | C8: 1 | D8: 0 | E8: 1 | F8: 5 | G8: {=_xlfn.IFS(AND(F8>=5,F8<12),"Morning",AND(F8>=12,F8<17),"AfterNoon",AND(F8>=17,F8<20),"Evening",TRUE,"Night")} -> Morning | H8: FALSE | I8: 6 | J8: {=_xlfn.IFS(I8=0,"Saturday",I8=1,"Sunday",I8=2,"Monday",I8=3,"Tuesday",I8=4,"Wednesday",I8=5,"Thusday",I8=6,"Friday")} -> Friday | K8: 2 | L8: 0.24 | M8: =IF(L8<=0.1,"Stromy",IF(L8<=0.2,"Rainy",IF(L8<=0.3,"Cloudy","Sunny"))) -> Cloudy
A9: 7 | B9: 40544 | C9: 1 | D9: 0 | E9: 1 | F9: 6 | G9: {=_xlfn.IFS(AND(F9>=5,F9<12),"Morning",AND(F9>=12,F9<17),"AfterNoon",AND(F9>=17,F9<20),"Evening",TRUE,"Night")} -> Morning | H9: FALSE | I9: 6 | J9: {=_xlfn.IFS(I9=0,"Saturday",I9=1,"Sunday",I9=2,"Monday",I9=3,"Tuesday",I9=4,"Wednesday",I9=5,"Thusday",I9=6,"Friday")} -> Friday | K9: 1 | L9: 0.22 | M9: =IF(L9<=0.1,"Stromy",IF(L9<=0.2,"Rainy",IF(L9<=0.3,"Cloudy","Sunny"))) -> Cloudy
A10: 8 | B10: 40544 | C10: 1 | D10: 0 | E10: 1 | F10: 7 | G10: {=_xlfn.IFS(AND(F10>=5,F10<12),"Morning",AND(F10>=12,F10<17),"AfterNoon",AND(F10>=17,F10<20),"Evening",TRUE,"Night")} -> Morning | H10: FALSE | I10: 6 | J10: {=_xlfn.IFS(I10=0,"Saturday",I10=1,"Sunday",I10=2,"Monday",I10=3,"Tuesday",I10=4,"Wednesday",I10=5,"Thusday",I10=6,"Friday")} -> Friday | K10: 1 | L10: 0.2 | M10: =IF(L10<=0.1,"Stromy",IF(L10<=0.2,"Rainy",IF(L10<=0.3,"Cloudy","Sunny"))) -> Rainy
A11: 9 | B11: 40544 | C11: 1 | D11: 0 | E11: 1 | F11: 8 | G11: {=_xlfn.IFS(AND(F11>=5,F11<12),"Morning",AND(F11>=12,F11<17),"AfterNoon",AND(F11>=17,F11<20),"Evening",TRUE,"Night")} -> Morning | H11: FALSE | I11: 6 | J11: {=_xlfn.IFS(I11=0,"Saturday",I11=1,"Sunday",I11=2,"Monday",I11=3,"Tuesday",I11=4,"Wednesday",I11=5,"Thusday",I11=6,"Friday")} -> Friday | K11: 1 | L11: 0.24 | M11: =IF(L11<=0.1,"Stromy",IF(L11<=0.2,"Rainy",IF(L11<=0.3,"Cloudy","Sunny"))) -> Cloudy
A12: 10 | B12: 40544 | C12: 1 | D12: 0 | E12: 1 | F12: 9 | G12: {=_xlfn.IFS(AND(F12>=5,F12<12),"Morning",AND(F12>=12,F12<17),"AfterNoon",AND(F12>=17,F12<20),"Evening",TRUE,"Night")} -> Morning | H12: FALSE | I12: 6 | J12: {=_xlfn.IFS(I12=0,"Saturday",I12=1,"Sunday",I12=2,"Monday",I12=3,"Tuesday",I12=4,"Wednesday",I12=5,"Thusday",I12=6,"Friday")} -> Friday | K12: 1 | L12: 0.32 | M12: =IF(L12<=0.1,"Stromy",IF(L12<=0.2,"Rainy",IF(L12<=0.3,"Cloudy","Sunny"))) -> Sunny
A13: 11 | B13: 40544 | C13: 1 | D13: 0 | E13: 1 | F13: 10 | G13: {=_xlfn.IFS(AND(F13>=5,F13<12),"Morning",AND(F13>=12,F13<17),"AfterNoon",AND(F13>=17,F13<20),"Evening",TRUE,"Night")} -> Morning | H13: FALSE | I13: 6 | J13: {=_xlfn.IFS(I13=0,"Saturday",I13=1,"Sunday",I13=2,"Monday",I13=3,"Tuesday",I13=4,"Wednesday",I13=5,"Thusday",I13=6,"Friday")} -> Friday | K13: 1 | L13: 0.38 | M13: =IF(L13<=0.1,"Stromy",IF(L13<=0.2,"Rainy",IF(L13<=0.3,"Cloudy","Sunny"))) -> Sunny
A14: 12 | B14: 40544 | C14: 1 | D14: 0 | E14: 1 | F14: 11 | G14: {=_xlfn.IFS(AND(F14>=5,F14<12),"Morning",AND(F14>=12,F14<17),"AfterNoon",AND(F14>=17,F14<20),"Evening",TRUE,"Night")} -> Morning | H14: FALSE | I14: 6 | J14: {=_xlfn.IFS(I14=0,"Saturday",I14=1,"Sunday",I14=2,"Monday",I14=3,"Tuesday",I14=4,"Wednesday",I14=5,"Thusday",I14=6,"Friday")} -> Friday | K14: 1 | L14: 0.36 | M14: =IF(L14<=0.1,"Stromy",IF(L14<=0.2,"Rainy",IF(L14<=0.3,"Cloudy","Sunny"))) -> Sunny
... A612: 610 | B612: 40571 | C612: 1 | D612: 0 | E612: 1 | F612: 15 | G612: {=_xlfn.IFS(AND(F612>=5,F612<12),"Morning",AND(F612>=12,F612<17),"AfterNoon",AND(F612>=17,F612<20),"Evening",TRUE,"Night")} -> AfterNoon | H612: FALSE | I612: 5 | J612: {=_xlfn.IFS(I612=0,"Saturday",I612=1,"Sunday",I612=2,"Monday",I612=3,"Tuesday",I612=4,"Wednesday",I612=5,"Thusday",I612=6,"Friday")} -> Thusday | K612: 2 | L612: 0.2 | M612: =IF(L612<=0.1,"Stromy",IF(L612<=0.2,"Rainy",IF(L612<=0.3,"Cloudy","Sunny"))) -> Rainy
F613: Total Hrs | I613: Total Weakdays | L613: Total Temp
F614: =SUM(F2:F612) -> 7195 | I614: =SUM(I2:I612) -> 1816 | L614: =SUM(L2:L612) -> 120.1
F615: Average | I615: Average | L615: Average
F616: =AVERAGE(F2:F612) -> 11.795082 | I616: =AVERAGE(I2:I612) -> 2.9770492 | L616: =AVERAGE(L2:L612) -> 0.19688525

Sheet Dataset-2
A1: atemp | B1: instant | C1: N Atemp | D1: hum | E1: windspeed | F1: casual | G1: registered | H1: cnt
A2: =PROPER(A1) -> Atemp | B2: =PROPER(B1) -> Instant | C2: =PROPER(C1) -> N Atemp | D2: =PROPER(D1) -> Hum | E2: =PROPER(E1) -> Windspeed | F2: =PROPER(F1) -> Casual | G2: =PROPER(G1) -> Registered | H2: =PROPER(H1) -> Cnt
A3: 0.2879 | B3: 1 | C3: =IF(ISBLANK(A3),AVERAGE(A2:A4),A3) -> 0.2879 | D3: 0.81 | E3: 0 | F3: 3 | G3: 13 | H3: 16
A4: 0.2727 | B4: 2 | C4: =IF(ISBLANK(A4),AVERAGE(A3:A5),A4) -> 0.2727 | D4: 0.8 | E4: 0 | F4: 8 | G4: 32 | H4: 40
A5: 0.2727 | B5: 3 | C5: =IF(ISBLANK(A5),AVERAGE(A4:A6),A5) -> 0.2727 | D5: 0.8 | E5: 0 | F5: 5 | G5: 27 | H5: 32
A6: 0.2879 | B6: 4 | C6: =IF(ISBLANK(A6),AVERAGE(A5:A7),A6) -> 0.2879 | D6: 0.75 | E6: 0 | F6: 3 | G6: 10 | H6: 13
A7: 0.2879 | B7: 5 | C7: =IF(ISBLANK(A7),AVERAGE(A6:A8),A7) -> 0.2879 | D7: 0.75 | E7: 0 | F7: 0 | G7: 1 | H7: 1
A8: 0.2576 | B8: 6 | C8: =IF(ISBLANK(A8),AVERAGE(A7:A9),A8) -> 0.2576 | D8: 0.75 | E8: 0.0896 | F8: 0 | G8: 1 | H8: 1
A9: 0.2727 | B9: 7 | C9: =IF(ISBLANK(A9),AVERAGE(A8:A10),A9) -> 0.2727 | D9: 0.8 | E9: 0 | F9: 2 | G9: 0 | H9: 2
A10: 0.2576 | B10: 8 | C10: =IF(ISBLANK(A10),AVERAGE(A9:A11),A10) -> 0.2576 | D10: 0.86 | E10: 0 | F10: 1 | G10: 2 | H10: 3
B11: 9 | C11: =IF(ISBLANK(A11),AVERAGE(A10:A12),A11) -> 0.30305 | D11: 0.75 | E11: 0 | F11: 1 | G11: 7 | H11: 8
A12: 0.3485 | B12: 10 | C12: =IF(ISBLANK(A12),AVERAGE(A11:A13),A12) -> 0.3485 | D12: 0.76 | E12: 0 | F12: 8 | G12: 6 | H12: 14
A13: 0.3939 | B13: 11 | C13: =IF(ISBLANK(A13),AVERAGE(A12:A14),A13) -> 0.3939 | D13: 0.76 | E13: 0.2537 | F13: 12 | G13: 24 | H13: 36
A14: 0.3333 | B14: 12 | C14: =IF(ISBLANK(A14),AVERAGE(A13:A15),A14) -> 0.3333 | D14: 0.81 | E14: 0.2836 | F14: 26 | G14: 30 | H14: 56
A15: 0.4242 | B15: 13 | C15: =IF(ISBLANK(A15),AVERAGE(A14:A16),A15) -> 0.4242 | D15: 0.77 | E15: 0.2836 | F15: 29 | G15: 55 | H15: 84
A16: 0.4545 | B16: 14 | C16: =IF(ISBLANK(A16),AVERAGE(A15:A17),A16) -> 0.4545 | D16: 0.72 | E16: 0.2985 | F16: 47 | G16: 47 | H16: 94
A17: 0.4545 | B17: 15 | C17: =IF(ISBLANK(A17),AVERAGE(A16:A18),A17) -> 0.4545 | D17: 0.72 | E17: 0.2836 | F17: 35 | G17: 71 | H17: 106
A18: 0.4394 | B18: 16 | C18: =IF(ISBLANK(A18),AVERAGE(A17:A19),A18) -> 0.4394 | D18: 0.77 | E18: 0.2985 | F18: 40 | G18: 70 | H18: 110
A19: 0.4242 | B19: 17 | C19: =IF(ISBLANK(A19),AVERAGE(A18:A20),A19) -> 0.4242 | D19: 0.82 | E19: 0.2985 | F19: 41 | G19: 52 | H19: 93
B20: 18 | C20: =IF(ISBLANK(A20),AVERAGE(A19:A21),A20) -> 0.4242 | D20: 0.82 | E20: 0.2836 | F20: 15 | G20: 52 | H20: 67
A21: 0.4242 | B21: 19 | C21: =IF(ISBLANK(A21),AVERAGE(A20:A22),A21) -> 0.4242 | D21: 0.88 | E21: 0.2537 | F21: 9 | G21: 26 | H21: 35
A22: 0.4242 | B22: 20 | C22: =IF(ISBLANK(A22),AVERAGE(A21:A23),A22) -> 0.4242 | D22: 0.88 | E22: 0.2537 | F22: 6 | G22: 31 | H22: 37
A23: 0.4091 | B23: 21 | C23: =IF(ISBLANK(A23),AVERAGE(A22:A24),A23) -> 0.4091 | D23: 0.87 | E23: 0.2537 | F23: 11 | G23: 25 | H23: 36
A24: 0.4091 | B24: 22 | C24: =IF(ISBLANK(A24),AVERAGE(A23:A25),A24) -> 0.4091 | D24: 0.87 | E24: 0.194 | F24: 3 | G24: 31 | H24: 34
A25: 0.4091 | B25: 23 | C25: =IF(ISBLANK(A25),AVERAGE(A24:A26),A25) -> 0.4091 | D25: 0.94 | E25: 0.2239 | F25: 11 | G25: 17 | H25: 28
B26: 24 | C26: =IF(ISBLANK(A26),AVERAGE(A25:A27),A26) -> 0.4318 | D26: 0.88 | E26: 0.2985 | F26: 15 | G26: 24 | H26: 39
A27: 0.4545 | B27: 25 | C27: =IF(ISBLANK(A27),AVERAGE(A26:A28),A27) -> 0.4545 | D27: 0.88 | E27: 0.2985 | F27: 4 | G27: 13 | H27: 17
A28: 0.4394 | B28: 26 | C28: =IF(ISBLANK(A28),AVERAGE(A27:A29),A28) -> 0.4394 | D28: 0.94 | E28: 0.2537 | F28: 1 | G28: 16 | H28: 17
A29: 0.4242 | B29: 27 | C29: =IF(ISBLANK(A29),AVERAGE(A28:A30),A29) -> 0.4242 | D29: 1 | E29: 0.2836 | F29: 1 | G29: 8 | H29: 9
A30: 0.4545 | B30: 28 | C30: =IF(ISBLANK(A30),AVERAGE(A29:A31),A30) -> 0.4545 | D30: 0.94 | E30: 0.194 | F30: 2 | G30: 4 | H30: 6
B31: 29 | C31: =IF(ISBLANK(A31),AVERAGE(A30:A32),A31) -> 0.43935 | D31: 0.94 | E31: 0.194 | F31: 2 | G31: 1 | H31: 3
A32: 0.4242 | B32: 30 | C32: =IF(ISBLANK(A32),AVERAGE(A31:A33),A32) -> 0.4242 | D32: 0.77 | E32: 0.2985 | F32: 0 | G32: 2 | H32: 2
A33: 0.4091 | B33: 31 | C33: =IF(ISBLANK(A33),AVERAGE(A32:A34),A33) -> 0.4091 | D33: 0.76 | E33: 0.194 | F33: 0 | G33: 1 | H33: 1
A34: 0.4091 | B34: 32 | C34: =IF(ISBLANK(A34),AVERAGE(A33:A35),A34) -> 0.4091 | D34: 0.71 | E34: 0.2239 | F34: 0 | G34: 8 | H34: 8
B35: 33 | C35: =IF(ISBLANK(A35),AVERAGE(A34:A36),A35) -> 0.3788 | D35: 0.76 | E35: 0.2239 | F35: 1 | G35: 19 | H35: 20
A36: 0.3485 | B36: 34 | C36: =IF(ISBLANK(A36),AVERAGE(A35:A37),A36) -> 0.3485 | D36: 0.81 | E36: 0.2239 | F36: 7 | G36: 46 | H36: 53
A37: 0.3333 | B37: 35 | C37: =IF(ISBLANK(A37),AVERAGE(A36:A38),A37) -> 0.3333 | D37: 0.71 | E37: 0.2537 | F37: 16 | G37: 54 | H37: 70
A38: 0.3333 | B38: 36 | C38: =IF(ISBLANK(A38),AVERAGE(A37:A39),A38) -> 0.3333 | D38: 0.66 | E38: 0.2985 | F38: 20 | G38: 73 | H38: 93
A39: 0.3485 | B39: 37 | C39: =IF(ISBLANK(A39),AVERAGE(A38:A40),A39) -> 0.3485 | D39: 0.66 | E39: 0.1343 | F39: 11 | G39: 64 | H39: 75
B40: 38 | C40: =IF(ISBLANK(A40),AVERAGE(A39:A41),A40) -> 0.3409 | D40: 0.76 | E40: 0.194 | F40: 4 | G40: 55 | H40: 59
...

Sheet Dataset-3
A1: instant | B1: dteday | C1: season | D1: yr | E1: mnth | F1: hr | H1: holiday | I1: weekday | K1: weathersit | L1: temp | N1: n atemp | O1: hum | P1: windspeed | Q1: casual | R1: registered | S1: cnt
A2: =PROPER(A1) -> Instant | B2: =PROPER(B1) -> Dteday | C2: =PROPER(C1) -> Season | D2: =PROPER(D1) -> Yr | E2: =PROPER(E1) -> Mnth | F2: =PROPER(F1) -> Hr | G2: Time | H2: =PROPER(H1) -> Holiday | I2: =PROPER(I1) -> Weekday | J2: Days | K2: =PROPER(K1) -> Weathersit | L2: =PROPER(L1) -> Temp | M2: Weather | N2: =PROPER(N1) -> N Atemp | O2: =PROPER(O1) -> Hum | P2: =PROPER(P1) -> Windspeed | Q2: =PROPER(Q1) -> Casual | R2: =PROPER(R1) -> Registered | S2: =PROPER(S1) -> Cnt
A3: 611 | B3: 40571 | C3: 1 | D3: 0 | E3: 1 | F3: 16 | G3: {=_xlfn.IFS(AND(F3>=5,F3<12),"Morning",AND(F3>=12,F3<17),"AfterNoon",AND(F3>=17,F3<20),"Evening",TRUE,"Night")} -> AfterNoon | H3: FALSE | I3: 5 | J3: {=_xlfn.IFS(I3=0,"Saturday",I3=1,"Sunday",I3=2,"Monday",I3=3,"Tuesday",I3=4,"Wednesday",I3=5,"Thusday",I3=6,"Friday")} -> Thusday | K3: 1 | L3: 0.22 | M3: =IF(L3<=0.1,"Stromy",IF(L3<=0.2,"Rainy",IF(L3<=0.3,"Cloudy","Sunny"))) -> Cloudy | N3: 0.2727 | O3: 0.8 | P3: 0 | Q3: 10 | R3: 70 | S3: 80
A4: 612 | B4: 40571 | C4: 1 | D4: 0 | E4: 1 | F4: 17 | G4: {=_xlfn.IFS(AND(F4>=5,F4<12),"Morning",AND(F4>=12,F4<17),"AfterNoon",AND(F4>=17,F4<20),"Evening",TRUE,"Night")} -> Evening | H4: FALSE | I4: 5 | J4: {=_xlfn.IFS(I4=0,"Saturday",I4=1,"Sunday",I4=2,"Monday",I4=3,"Tuesday",I4=4,"Wednesday",I4=5,"Thusday",I4=6,"Friday")} -> Thusday | K4: 1 | L4: 0.24 | M4: =IF(L4<=0.1,"Stromy",IF(L4<=0.2,"Rainy",IF(L4<=0.3,"Cloudy","Sunny"))) -> Cloudy | N4: 0.2424 | O4: 0.75 | P4: 0.1343 | Q4: 2 | R4: 147 | S4: 149
A5: 613 | B5: 40571 | C5: 1 | D5: 0 | E5: 1 | F5: 18 | G5: {=_xlfn.IFS(AND(F5>=5,F5<12),"Morning",AND(F5>=12,F5<17),"AfterNoon",AND(F5>=17,F5<20),"Evening",TRUE,"Night")} -> Evening | H5: FALSE | I5: 5 | J5: {=_xlfn.IFS(I5=0,"Saturday",I5=1,"Sunday",I5=2,"Monday",I5=3,"Tuesday",I5=4,"Wednesday",I5=5,"Thusday",I5=6,"Friday")} -> Thusday | K5: 1 | L5: 0.24 | M5: =IF(L5<=0.1,"Stromy",IF(L5<=0.2,"Rainy",IF(L5<=0.3,"Cloudy","Sunny"))) -> Cloudy | N5: 0.2273 | O5: 0.75 | P5: 0.194 | Q5: 2 | R5: 107 | S5: 109
A6: 614 | B6: 40571 | C6: 1 | D6: 0 | E6: 1 | F6: 19 | G6: {=_xlfn.IFS(AND(F6>=5,F6<12),"Morning",AND(F6>=12,F6<17),"AfterNoon",AND(F6>=17,F6<20),"Evening",TRUE,"Night")} -> Evening | H6: FALSE | I6: 5 | J6: {=_xlfn.IFS(I6=0,"Saturday",I6=1,"Sunday",I6=2,"Monday",I6=3,"Tuesday",I6=4,"Wednesday",I6=5,"Thusday",I6=6,"Friday")} -> Thusday | K6: 2 | L6: 0.24 | M6: =IF(L6<=0.1,"Stromy",IF(L6<=0.2,"Rainy",IF(L6<=0.3,"Cloudy","Sunny"))) -> Cloudy | N6: 0.2424 | O6: 0.75 | P6: 0.1343 | Q6: 5 | R6: 84 | S6: 89
A7: 615 | B7: 40571 | C7: 1 | D7: 0 | E7: 1 | F7: 20 | G7: {=_xlfn.IFS(AND(F7>=5,F7<12),"Morning",AND(F7>=12,F7<17),"AfterNoon",AND(F7>=17,F7<20),"Evening",TRUE,"Night")} -> Night | H7: FALSE | I7: 5 | J7: {=_xlfn.IFS(I7=0,"Saturday",I7=1,"Sunday",I7=2,"Monday",I7=3,"Tuesday",I7=4,"Wednesday",I7=5,"Thusday",I7=6,"Friday")} -> Thusday | K7: 2 | L7: 0.24 | M7: =IF(L7<=0.1,"Stromy",IF(L7<=0.2,"Rainy",IF(L7<=0.3,"Cloudy","Sunny"))) -> Cloudy | N7: 0.2273 | O7: 0.7 | P7: 0.194 | Q7: 1 | R7: 61 | S7: 62
A8: 616 | B8: 40571 | C8: 1 | D8: 0 | E8: 1 | F8: 21 | G8: {=_xlfn.IFS(AND(F8>=5,F8<12),"Morning",AND(F8>=12,F8<17),"AfterNoon",AND(F8>=17,F8<20),"Evening",TRUE,"Night")} -> Night | H8: FALSE | I8: 5 | J8: {=_xlfn.IFS(I8=0,"Saturday",I8=1,"Sunday",I8=2,"Monday",I8=3,"Tuesday",I8=4,"Wednesday",I8=5,"Thusday",I8=6,"Friday")} -> Thusday | K8: 2 | L8: 0.22 | M8: =IF(L8<=0.1,"Stromy",IF(L8<=0.2,"Rainy",IF(L8<=0.3,"Cloudy","Sunny"))) -> Cloudy | N8: 0.2273 | O8: 0.75 | P8: 0.1343 | Q8: 1 | R8: 57 | S8: 58
A9: 617 | B9: 40571 | C9: 1 | D9: 0 | E9: 1 | F9: 22 | G9: {=_xlfn.IFS(AND(F9>=5,F9<12),"Morning",AND(F9>=12,F9<17),"AfterNoon",AND(F9>=17,F9<20),"Evening",TRUE,"Night")} -> Night | H9: FALSE | I9: 5 | J9: {=_xlfn.IFS(I9=0,"Saturday",I9=1,"Sunday",I9=2,"Monday",I9=3,"Tuesday",I9=4,"Wednesday",I9=5,"Thusday",I9=6,"Friday")} -> Thusday | K9: 1 | L9: 0.24 | M9: =IF(L9<=0.1,"Stromy",IF(L9<=0.2,"Rainy",IF(L9<=0.3,"Cloudy","Sunny"))) -> Cloudy | N9: 0.2121 | O9: 0.65 | P9: 0.3582 | Q9: 0 | R9: 26 | S9: 26
A10: 618 | B10: 40571 | C10: 1 | D10: 0 | E10: 1 | F10: 23 | G10: {=_xlfn.IFS(AND(F10>=5,F10<12),"Morning",AND(F10>=12,F10<17),"AfterNoon",AND(F10>=17,F10<20),"Evening",TRUE,"Night")} -> Night | H10: FALSE | I10: 5 | J10: {=_xlfn.IFS(I10=0,"Saturday",I10=1,"Sunday",I10=2,"Monday",I10=3,"Tuesday",I10=4,"Wednesday",I10=5,"Thusday",I10=6,"Friday")} -> Thusday | K10: 1 | L10: 0.24 | M10: =IF(L10<=0.1,"Stromy",IF(L10<=0.2,"Rainy",IF(L10<=0.3,"Cloudy","Sunny"))) -> Cloudy | N10: 0.2273 | O10: 0.6 | P10: 0.2239 | Q10: 1 | R10: 22 | S10: 23
A11: 619 | B11: 40572 | C11: 1 | D11: 0 | E11: 1 | F11: 0 | G11: {=_xlfn.IFS(AND(F11>=5,F11<12),"Morning",AND(F11>=12,F11<17),"AfterNoon",AND(F11>=17,F11<20),"Evening",TRUE,"Night")} -> Night | H11: FALSE | I11: 6 | J11: {=_xlfn.IFS(I11=0,"Saturday",I11=1,"Sunday",I11=2,"Monday",I11=3,"Tuesday",I11=4,"Wednesday",I11=5,"Thusday",I11=6,"Friday")} -> Friday | K11: 1 | L11: 0.22 | M11: =IF(L11<=0.1,"Stromy",IF(L11<=0.2,"Rainy",IF(L11<=0.3,"Cloudy","Sunny"))) -> Cloudy | N11: 0.197 | O11: 0.64 | P11: 0.3582 | Q11: 2 | R11: 26 | S11: 28
A12: 620 | B12: 40572 | C12: 1 | D12: 0 | E12: 1 | F12: 1 | G12: {=_xlfn.IFS(AND(F12>=5,F12<12),"Morning",AND(F12>=12,F12<17),"AfterNoon",AND(F12>=17,F12<20),"Evening",TRUE,"Night")} -> Night | H12: FALSE | I12: 6 | J12: {=_xlfn.IFS(I12=0,"Saturday",I12=1,"Sunday",I12=2,"Monday",I12=3,"Tuesday",I12=4,"Wednesday",I12=5,"Thusday",I12=6,"Friday")} -> Friday | K12: 1 | L12: 0.22 | M12: =IF(L12<=0.1,"Stromy",IF(L12<=0.2,"Rainy",IF(L12<=0.3,"Cloudy","Sunny"))) -> Cloudy | N12: 0.2273 | O12: 0.64 | P12: 0.194 | Q12: 0 | R12: 20 | S12: 20
A13: 621 | B13: 40572 | C13: 1 | D13: 0 | E13: 1 | F13: 2 | G13: {=_xlfn.IFS(AND(F13>=5,F13<12),"Morning",AND(F13>=12,F13<17),"AfterNoon",AND(F13>=17,F13<20),"Evening",TRUE,"Night")} -> Night | H13: FALSE | I13: 6 | J13: {=_xlfn.IFS(I13=0,"Saturday",I13=1,"Sunday",I13=2,"Monday",I13=3,"Tuesday",I13=4,"Wednesday",I13=5,"Thusday",I13=6,"Friday")} -> Friday | K13: 1 | L13: 0.22 | M13: =IF(L13<=0.1,"Stromy",IF(L13<=0.2,"Rainy",IF(L13<=0.3,"Cloudy","Sunny"))) -> Cloudy | N13: 0.2273 | O13: 0.64 | P13: 0.1642 | Q13: 0 | R13: 15 | S13: 15
A14: 622 | B14: 40572 | C14: 1 | D14: 0 | E14: 1 | F14: 3 | G14: {=_xlfn.IFS(AND(F14>=5,F14<12),"Morning",AND(F14>=12,F14<17),"AfterNoon",AND(F14>=17,F14<20),"Evening",TRUE,"Night")} -> Night | H14: FALSE | I14: 6 | J14: {=_xlfn.IFS(I14=0,"Saturday",I14=1,"Sunday",I14=2,"Monday",I14=3,"Tuesday",I14=4,"Wednesday",I14=5,"Thusday",I14=6,"Friday")} -> Friday | K14: 1 | L14: 0.2 | M14: =IF(L14<=0.1,"Stromy",IF(L14<=0.2,"Rainy",IF(L14<=0.3,"Cloudy","Sunny"))) -> Rainy | N14: 0.2121 | O14: 0.64 | P14: 0.1343 | Q14: 3 | R14: 5 | S14: 8
... A392: 1000 | B392: 40588 | C392: 1 | D392: 0 | E392: 2 | F392: 7 | G392: {=_xlfn.IFS(AND(F392>=5,F392<12),"Morning",AND(F392>=12,F392<17),"AfterNoon",AND(F392>=17,F392<20),"Evening",TRUE,"Night")} -> Morning | H392: FALSE | I392: 1 | J392: {=_xlfn.IFS(I392=0,"Saturday",I392=1,"Sunday",I392=2,"Monday",I392=3,"Tuesday",I392=4,"Wednesday",I392=5,"Thusday",I392=6,"Friday")} -> Sunday | K392: 1 | L392: 0.34 | M392: =IF(L392<=0.1,"Stromy",IF(L392<=0.2,"Rainy",IF(L392<=0.3,"Cloudy","Sunny"))) -> Sunny | N392: 0.303 | O392: 0.46 | P392: 0.2985 | Q392: 2 | R392: 96 | S392: 98

Sheet Sheet A
A1: Instant | B1: =VLOOKUP(A1,'Dataset-1'!A2:M612,2,) -> Dteday | C1: =VLOOKUP(B1,'Dataset-1'!B2:N612,2,) -> Season | D1: =VLOOKUP(C1,'Dataset-1'!C2:O612,2,) -> Yr | E1: =VLOOKUP(D1,'Dataset-1'!D2:P612,2,) -> Mnth | F1: =VLOOKUP(E1,'Dataset-1'!E2:Q612,2,) -> Hr | G1: =VLOOKUP(F1,'Dataset-1'!F2:R612,2,) -> Time | H1: =VLOOKUP(G1,'Dataset-1'!G2:S612,2,) -> Holiday | I1: =VLOOKUP(H1,'Dataset-1'!H2:T612,2,) -> Weekday | ... M1: =VLOOKUP(L1,'Dataset-1'!L2:X612,2,) -> Weather | N1: =VLOOKUP(A1,'Dataset-2'!B2:H612,2,) -> N Atemp | O1: =VLOOKUP(N1,'Dataset-2'!C2:I612,2,) -> Hum | P1: =VLOOKUP(O1,'Dataset-2'!D2:J612,2,) -> Windspeed | Q1: =VLOOKUP(P1,'Dataset-2'!E2:K612,2,) -> Casual | R1: =VLOOKUP(Q1,'Dataset-2'!F2:L612,2,) -> Registered | S1: =VLOOKUP(R1,'Dataset-2'!G2:M612,2,) -> Cnt
A2: 1 | B2: =VLOOKUP(A2,'Dataset-1'!A3:M613,2,) -> 40544 | C2: =VLOOKUP(B2,'Dataset-1'!B3:N613,2,) -> 1 | D2: =VLOOKUP(C2,'Dataset-1'!C3:O613,2,) -> 0 | E2: =VLOOKUP(D2,'Dataset-1'!D3:P613,2,) -> 1 | F2: =VLOOKUP(E2,'Dataset-1'!E3:Q613,2,) -> 0 | G2: =VLOOKUP(F2,'Dataset-1'!F3:R613,2,) -> Night | H2: =VLOOKUP(G2,'Dataset-1'!G3:S613,2,) -> FALSE | I2: =VLOOKUP(H2,'Dataset-1'!H3:T613,2,) -> 6 | ... M2: =VLOOKUP(L2,'Dataset-1'!L3:X613,2,) -> Cloudy | N2: =VLOOKUP(A2,'Dataset-2'!B3:H613,2,) -> 0.2879 | O2: =VLOOKUP(N2,'Dataset-2'!C3:I613,2,) -> 0.81 | P2: =VLOOKUP(O2,'Dataset-2'!D3:J613,2,) -> 0 | Q2: =VLOOKUP(P2,'Dataset-2'!E3:K613,2,) -> 3 | R2: =VLOOKUP(Q2,'Dataset-2'!F3:L613,2,) -> 13 | S2: =VLOOKUP(R2,'Dataset-2'!G3:M613,2,) -> 16
A3: 2 | B3: =VLOOKUP(A3,'Dataset-1'!A4:M614,2,) -> 40544 | C3: =VLOOKUP(B3,'Dataset-1'!B4:N614,2,) -> 1 | D3: =VLOOKUP(C3,'Dataset-1'!C4:O614,2,) -> 0 | E3: =VLOOKUP(D3,'Dataset-1'!D4:P614,2,) -> 1 | F3: =VLOOKUP(E3,'Dataset-1'!E4:Q614,2,) -> 1 | G3: =VLOOKUP(F3,'Dataset-1'!F4:R614,2,) -> Night | H3: =VLOOKUP(G3,'Dataset-1'!G4:S614,2,) -> FALSE | I3: =VLOOKUP(H3,'Dataset-1'!H4:T614,2,) -> 6 | ... M3: =VLOOKUP(L3,'Dataset-1'!L4:X614,2,) -> Cloudy | N3: =VLOOKUP(A3,'Dataset-2'!B4:H614,2,) -> 0.2727 | O3: =VLOOKUP(N3,'Dataset-2'!C4:I614,2,) -> 0.8 | P3: =VLOOKUP(O3,'Dataset-2'!D4:J614,2,) -> 0 | Q3: =VLOOKUP(P3,'Dataset-2'!E4:K614,2,) -> 8 | R3: =VLOOKUP(Q3,'Dataset-2'!F4:L614,2,) -> 32 | S3: =VLOOKUP(R3,'Dataset-2'!G4:M614,2,) -> 40
A4: 3 | B4: =VLOOKUP(A4,'Dataset-1'!A5:M615,2,) -> 40544 | C4: =VLOOKUP(B4,'Dataset-1'!B5:N615,2,) -> 1 | D4: =VLOOKUP(C4,'Dataset-1'!C5:O615,2,) -> 0 | E4: =VLOOKUP(D4,'Dataset-1'!D5:P615,2,) -> 1 | F4: =VLOOKUP(E4,'Dataset-1'!E5:Q615,2,) -> 2 | G4: =VLOOKUP(F4,'Dataset-1'!F5:R615,2,) -> Night | H4: =VLOOKUP(G4,'Dataset-1'!G5:S615,2,) -> FALSE | I4: =VLOOKUP(H4,'Dataset-1'!H5:T615,2,) -> 6 | ... M4: =VLOOKUP(L4,'Dataset-1'!L5:X615,2,) -> Cloudy | N4: =VLOOKUP(A4,'Dataset-2'!B5:H615,2,) -> 0.2727 | O4: =VLOOKUP(N4,'Dataset-2'!C5:I615,2,) -> 0.8 | P4: =VLOOKUP(O4,'Dataset-2'!D5:J615,2,) -> 0 | Q4: =VLOOKUP(P4,'Dataset-2'!E5:K615,2,) -> 5 | R4: =VLOOKUP(Q4,'Dataset-2'!F5:L615,2,) -> 27 | S4: =VLOOKUP(R4,'Dataset-2'!G5:M615,2,) -> 32
A5: 4 | B5: =VLOOKUP(A5,'Dataset-1'!A6:M616,2,) -> 40544 | C5: =VLOOKUP(B5,'Dataset-1'!B6:N616,2,) -> 1 | D5: =VLOOKUP(C5,'Dataset-1'!C6:O616,2,) -> 0 | E5: =VLOOKUP(D5,'Dataset-1'!D6:P616,2,) -> 1 | F5: =VLOOKUP(E5,'Dataset-1'!E6:Q616,2,) -> 3 | G5: =VLOOKUP(F5,'Dataset-1'!F6:R616,2,) -> Night | H5: =VLOOKUP(G5,'Dataset-1'!G6:S616,2,) -> FALSE | I5: =VLOOKUP(H5,'Dataset-1'!H6:T616,2,) -> 6 | ... M5: =VLOOKUP(L5,'Dataset-1'!L6:X616,2,) -> Cloudy | N5: =VLOOKUP(A5,'Dataset-2'!B6:H616,2,) -> 0.2879 | O5: =VLOOKUP(N5,'Dataset-2'!C6:I616,2,) -> 0.75 | P5: =VLOOKUP(O5,'Dataset-2'!D6:J616,2,) -> 0 | Q5: =VLOOKUP(P5,'Dataset-2'!E6:K616,2,) -> 3 | R5: =VLOOKUP(Q5,'Dataset-2'!F6:L616,2,) -> 10 | S5: =VLOOKUP(R5,'Dataset-2'!G6:M616,2,) -> 13
A6: 5 | B6: =VLOOKUP(A6,'Dataset-1'!A7:M617,2,) -> 40544 | C6: =VLOOKUP(B6,'Dataset-1'!B7:N617,2,) -> 1 | D6: =VLOOKUP(C6,'Dataset-1'!C7:O617,2,) -> 0 | E6: =VLOOKUP(D6,'Dataset-1'!D7:P617,2,) -> 1 | F6: =VLOOKUP(E6,'Dataset-1'!E7:Q617,2,) -> 4 | G6: =VLOOKUP(F6,'Dataset-1'!F7:R617,2,) -> Night | H6: =VLOOKUP(G6,'Dataset-1'!G7:S617,2,) -> FALSE | I6: =VLOOKUP(H6,'Dataset-1'!H7:T617,2,) -> 6 | ... M6: =VLOOKUP(L6,'Dataset-1'!L7:X617,2,) -> Cloudy | N6: =VLOOKUP(A6,'Dataset-2'!B7:H617,2,) -> 0.2879 | O6: =VLOOKUP(N6,'Dataset-2'!C7:I617,2,) -> 0.75 | P6: =VLOOKUP(O6,'Dataset-2'!D7:J617,2,) -> 0 | Q6: =VLOOKUP(P6,'Dataset-2'!E7:K617,2,) -> 0 | R6: =VLOOKUP(Q6,'Dataset-2'!F7:L617,2,) -> 1 | S6: =VLOOKUP(R6,'Dataset-2'!G7:M617,2,) -> 1
A7: 6 | B7: =VLOOKUP(A7,'Dataset-1'!A8:M618,2,) -> 40544 | C7: =VLOOKUP(B7,'Dataset-1'!B8:N618,2,) -> 1 | D7: =VLOOKUP(C7,'Dataset-1'!C8:O618,2,) -> 0 | E7: =VLOOKUP(D7,'Dataset-1'!D8:P618,2,) -> 1 | F7: =VLOOKUP(E7,'Dataset-1'!E8:Q618,2,) -> 5 | G7: =VLOOKUP(F7,'Dataset-1'!F8:R618,2,) -> Morning | H7: =VLOOKUP(G7,'Dataset-1'!G8:S618,2,) -> FALSE | I7: =VLOOKUP(H7,'Dataset-1'!H8:T618,2,) -> 6 | ... M7: =VLOOKUP(L7,'Dataset-1'!L8:X618,2,) -> Cloudy | N7: =VLOOKUP(A7,'Dataset-2'!B8:H618,2,) -> 0.2576 | O7: =VLOOKUP(N7,'Dataset-2'!C8:I618,2,) -> 0.75 | P7: =VLOOKUP(O7,'Dataset-2'!D8:J618,2,) -> 0.0896 | Q7: =VLOOKUP(P7,'Dataset-2'!E8:K618,2,) -> 0 | R7: =VLOOKUP(Q7,'Dataset-2'!F8:L618,2,) -> 1 | S7: =VLOOKUP(R7,'Dataset-2'!G8:M618,2,) -> 1
A8: 7 | B8: =VLOOKUP(A8,'Dataset-1'!A9:M619,2,) -> 40544 | C8: =VLOOKUP(B8,'Dataset-1'!B9:N619,2,) -> 1 | D8: =VLOOKUP(C8,'Dataset-1'!C9:O619,2,) -> 0 | E8: =VLOOKUP(D8,'Dataset-1'!D9:P619,2,) -> 1 | F8: =VLOOKUP(E8,'Dataset-1'!E9:Q619,2,) -> 6 | G8: =VLOOKUP(F8,'Dataset-1'!F9:R619,2,) -> Morning | H8: =VLOOKUP(G8,'Dataset-1'!G9:S619,2,) -> FALSE | I8: =VLOOKUP(H8,'Dataset-1'!H9:T619,2,) -> 6 | ... M8: =VLOOKUP(L8,'Dataset-1'!L9:X619,2,) -> Cloudy | N8: =VLOOKUP(A8,'Dataset-2'!B9:H619,2,) -> 0.2727 | O8: =VLOOKUP(N8,'Dataset-2'!C9:I619,2,) -> 0.8 | P8: =VLOOKUP(O8,'Dataset-2'!D9:J619,2,) -> 0 | Q8: =VLOOKUP(P8,'Dataset-2'!E9:K619,2,) -> 2 | R8: =VLOOKUP(Q8,'Dataset-2'!F9:L619,2,) -> 0 | S8: =VLOOKUP(R8,'Dataset-2'!G9:M619,2,) -> 2
A9: 8 | B9: =VLOOKUP(A9,'Dataset-1'!A10:M620,2,) -> 40544 | C9: =VLOOKUP(B9,'Dataset-1'!B10:N620,2,) -> 1 | D9: =VLOOKUP(C9,'Dataset-1'!C10:O620,2,) -> 0 | E9: =VLOOKUP(D9,'Dataset-1'!D10:P620,2,) -> 1 | F9: =VLOOKUP(E9,'Dataset-1'!E10:Q620,2,) -> 7 | G9: =VLOOKUP(F9,'Dataset-1'!F10:R620,2,) -> Morning | H9: =VLOOKUP(G9,'Dataset-1'!G10:S620,2,) -> FALSE | I9: =VLOOKUP(H9,'Dataset-1'!H10:T620,2,) -> 6 | ... M9: =VLOOKUP(L9,'Dataset-1'!L10:X620,2,) -> Rainy | N9: =VLOOKUP(A9,'Dataset-2'!B10:H620,2,) -> 0.2576 | O9: =VLOOKUP(N9,'Dataset-2'!C10:I620,2,) -> 0.86 | P9: =VLOOKUP(O9,'Dataset-2'!D10:J620,2,) -> 0 | Q9: =VLOOKUP(P9,'Dataset-2'!E10:K620,2,) -> 1 | R9: =VLOOKUP(Q9,'Dataset-2'!F10:L620,2,) -> 2 | S9: =VLOOKUP(R9,'Dataset-2'!G10:M620,2,) -> 3
A10: 9 | B10: =VLOOKUP(A10,'Dataset-1'!A11:M621,2,) -> 40544 | C10: =VLOOKUP(B10,'Dataset-1'!B11:N621,2,) -> 1 | D10: =VLOOKUP(C10,'Dataset-1'!C11:O621,2,) -> 0 | E10: =VLOOKUP(D10,'Dataset-1'!D11:P621,2,) -> 1 | F10: =VLOOKUP(E10,'Dataset-1'!E11:Q621,2,) -> 8 | G10: =VLOOKUP(F10,'Dataset-1'!F11:R621,2,) -> Morning | H10: =VLOOKUP(G10,'Dataset-1'!G11:S621,2,) -> FALSE | I10: =VLOOKUP(H10,'Dataset-1'!H11:T621,2,) -> 6 | ... M10: =VLOOKUP(L10,'Dataset-1'!L11:X621,2,) -> Cloudy | N10: =VLOOKUP(A10,'Dataset-2'!B11:H621,2,) -> 0.30305 | O10: =VLOOKUP(N10,'Dataset-2'!C11:I621,2,) -> 0.75 | P10: =VLOOKUP(O10,'Dataset-2'!D11:J621,2,) -> 0 | Q10: =VLOOKUP(P10,'Dataset-2'!E11:K621,2,) -> 1 | R10: =VLOOKUP(Q10,'Dataset-2'!F11:L621,2,) -> 7 | S10: =VLOOKUP(R10,'Dataset-2'!G11:M621,2,) -> 8
A11: 10 | B11: =VLOOKUP(A11,'Dataset-1'!A12:M622,2,) -> 40544 | C11: =VLOOKUP(B11,'Dataset-1'!B12:N622,2,) -> 1 | D11: =VLOOKUP(C11,'Dataset-1'!C12:O622,2,) -> 0 | E11: =VLOOKUP(D11,'Dataset-1'!D12:P622,2,) -> 1 | F11: =VLOOKUP(E11,'Dataset-1'!E12:Q622,2,) -> 9 | G11: =VLOOKUP(F11,'Dataset-1'!F12:R622,2,) -> Morning | H11: =VLOOKUP(G11,'Dataset-1'!G12:S622,2,) -> FALSE | I11: =VLOOKUP(H11,'Dataset-1'!H12:T622,2,) -> 6 | ... M11: =VLOOKUP(L11,'Dataset-1'!L12:X622,2,) -> Sunny | N11: =VLOOKUP(A11,'Dataset-2'!B12:H622,2,) -> 0.3485 | O11: =VLOOKUP(N11,'Dataset-2'!C12:I622,2,) -> 0.76 | P11: =VLOOKUP(O11,'Dataset-2'!D12:J622,2,) -> 0 | Q11: =VLOOKUP(P11,'Dataset-2'!E12:K622,2,) -> 8 | R11: =VLOOKUP(Q11,'Dataset-2'!F12:L622,2,) -> 6 | S11: =VLOOKUP(R11,'Dataset-2'!G12:M622,2,) -> 14
A12: 11 | B12: =VLOOKUP(A12,'Dataset-1'!A13:M623,2,) -> 40544 | C12: =VLOOKUP(B12,'Dataset-1'!B13:N623,2,) -> 1 | D12: =VLOOKUP(C12,'Dataset-1'!C13:O623,2,) -> 0 | E12: =VLOOKUP(D12,'Dataset-1'!D13:P623,2,) -> 1 | F12: =VLOOKUP(E12,'Dataset-1'!E13:Q623,2,) -> 10 | G12: =VLOOKUP(F12,'Dataset-1'!F13:R623,2,) -> Morning | H12: =VLOOKUP(G12,'Dataset-1'!G13:S623,2,) -> FALSE | I12: =VLOOKUP(H12,'Dataset-1'!H13:T623,2,) -> 6 | ... M12: =VLOOKUP(L12,'Dataset-1'!L13:X623,2,) -> Sunny | N12: =VLOOKUP(A12,'Dataset-2'!B13:H623,2,) -> 0.3939 | O12: =VLOOKUP(N12,'Dataset-2'!C13:I623,2,) -> 0.76 | P12: =VLOOKUP(O12,'Dataset-2'!D13:J623,2,) -> 0.2537 | Q12: =VLOOKUP(P12,'Dataset-2'!E13:K623,2,) -> 12 | R12: =VLOOKUP(Q12,'Dataset-2'!F13:L623,2,) -> 24 | S12: =VLOOKUP(R12,'Dataset-2'!G13:M623,2,) -> 36
A13: 12 | B13: =VLOOKUP(A13,'Dataset-1'!A14:M624,2,) -> 40544 | C13: =VLOOKUP(B13,'Dataset-1'!B14:N624,2,) -> 1 | D13: =VLOOKUP(C13,'Dataset-1'!C14:O624,2,) -> 0 | E13: =VLOOKUP(D13,'Dataset-1'!D14:P624,2,) -> 1 | F13: =VLOOKUP(E13,'Dataset-1'!E14:Q624,2,) -> 11 | G13: =VLOOKUP(F13,'Dataset-1'!F14:R624,2,) -> Morning | H13: =VLOOKUP(G13,'Dataset-1'!G14:S624,2,) -> FALSE | I13: =VLOOKUP(H13,'Dataset-1'!H14:T624,2,) -> 6 | ... M13: =VLOOKUP(L13,'Dataset-1'!L14:X624,2,) -> Sunny | N13: =VLOOKUP(A13,'Dataset-2'!B14:H624,2,) -> 0.3333 | O13: =VLOOKUP(N13,'Dataset-2'!C14:I624,2,) -> 0.81 | P13: =VLOOKUP(O13,'Dataset-2'!D14:J624,2,) -> 0.2836 | Q13: =VLOOKUP(P13,'Dataset-2'!E14:K624,2,) -> 26 | R13: =VLOOKUP(Q13,'Dataset-2'!F14:L624,2,) -> 30 | S13: =VLOOKUP(R13,'Dataset-2'!G14:M624,2,) -> 56
... A611: 610 | B611: =VLOOKUP(A611,'Dataset-1'!A612:M1222,2,) -> 40571 | C611: =VLOOKUP(B611,'Dataset-1'!B612:N1222,2,) -> 1 | D611: =VLOOKUP(C611,'Dataset-1'!C612:O1222,2,) -> 0 | E611: =VLOOKUP(D611,'Dataset-1'!D612:P1222,2,) -> 1 | F611: =VLOOKUP(E611,'Dataset-1'!E612:Q1222,2,) -> 15 | G611: =VLOOKUP(F611,'Dataset-1'!F612:R1222,2,) -> AfterNoon | H611: =VLOOKUP(G611,'Dataset-1'!G612:S1222,2,) -> FALSE | I611: =VLOOKUP(H611,'Dataset-1'!H612:T1222,2,) -> 5 | ... M611: =VLOOKUP(L611,'Dataset-1'!L612:X1222,2,) -> Rainy | N611: =VLOOKUP(A611,'Dataset-2'!B612:H1222,2,) -> 0.2576 | O611: =VLOOKUP(N611,'Dataset-2'!C612:I1222,2,) -> 0.86 | P611: =VLOOKUP(O611,'Dataset-2'!D612:J1222,2,) -> 0 | Q611: =VLOOKUP(P611,'Dataset-2'!E612:K1222,2,) -> 1 | R611: =VLOOKUP(Q611,'Dataset-2'!F612:L1222,2,) -> 40 | S611: =VLOOKUP(R611,'Dataset-2'!G612:M1222,2,) -> 41

Sheet Sheet B
A1: Instant | B1: =VLOOKUP(A1,'Sheet A'!A1:S611,2,) -> Dteday | C1: =VLOOKUP(B1,'Sheet A'!B1:T611,2,) -> Season | D1: =VLOOKUP(C1,'Sheet A'!C1:U611,2,) -> Yr | E1: =VLOOKUP(D1,'Sheet A'!D1:V611,2,) -> Mnth | F1: =VLOOKUP(E1,'Sheet A'!E1:W611,2,) -> Hr | G1: =VLOOKUP(F1,'Sheet A'!F1:X611,2,) -> Time | H1: =VLOOKUP(G1,'Sheet A'!G1:Y611,2,) -> Holiday | I1: =VLOOKUP(H1,'Sheet A'!H1:Z611,2,) -> Weekday | ... S1: =VLOOKUP(R1,'Sheet A'!R1:AJ611,2,) -> Cnt
A2: 1 | B2: =VLOOKUP(A2,'Sheet A'!A2:S612,2,) -> 40544 | C2: =VLOOKUP(B2,'Sheet A'!B2:T612,2,) -> 1 | D2: =VLOOKUP(C2,'Sheet A'!C2:U612,2,) -> 0 | E2: =VLOOKUP(D2,'Sheet A'!D2:V612,2,) -> 1 | F2: =VLOOKUP(E2,'Sheet A'!E2:W612,2,) -> 0 | G2: =VLOOKUP(F2,'Sheet A'!F2:X612,2,) -> Night | H2: =VLOOKUP(G2,'Sheet A'!G2:Y612,2,) -> FALSE | I2: =VLOOKUP(H2,'Sheet A'!H2:Z612,2,) -> 6 | ... S2: =VLOOKUP(R2,'Sheet A'!R2:AJ612,2,) -> 16
A3: 2 | B3: =VLOOKUP(A3,'Sheet A'!A3:S613,2,) -> 40544 | C3: =VLOOKUP(B3,'Sheet A'!B3:T613,2,) -> 1 | D3: =VLOOKUP(C3,'Sheet A'!C3:U613,2,) -> 0 | E3: =VLOOKUP(D3,'Sheet A'!D3:V613,2,) -> 1 | F3: =VLOOKUP(E3,'Sheet A'!E3:W613,2,) -> 1 | G3: =VLOOKUP(F3,'Sheet A'!F3:X613,2,) -> Night | H3: =VLOOKUP(G3,'Sheet A'!G3:Y613,2,) -> FALSE | I3: =VLOOKUP(H3,'Sheet A'!H3:Z613,2,) -> 6 | ... S3: =VLOOKUP(R3,'Sheet A'!R3:AJ613,2,) -> 40
A4: 3 | B4: =VLOOKUP(A4,'Sheet A'!A4:S614,2,) -> 40544 | C4: =VLOOKUP(B4,'Sheet A'!B4:T614,2,) -> 1 | D4: =VLOOKUP(C4,'Sheet A'!C4:U614,2,) -> 0 | E4: =VLOOKUP(D4,'Sheet A'!D4:V614,2,) -> 1 | F4: =VLOOKUP(E4,'Sheet A'!E4:W614,2,) -> 2 | G4: =VLOOKUP(F4,'Sheet A'!F4:X614,2,) -> Night | H4: =VLOOKUP(G4,'Sheet A'!G4:Y614,2,) -> FALSE | I4: =VLOOKUP(H4,'Sheet A'!H4:Z614,2,) -> 6 | ... S4: =VLOOKUP(R4,'Sheet A'!R4:AJ614,2,) -> 32
A5: 4 | B5: =VLOOKUP(A5,'Sheet A'!A5:S615,2,) -> 40544 | C5: =VLOOKUP(B5,'Sheet A'!B5:T615,2,) -> 1 | D5: =VLOOKUP(C5,'Sheet A'!C5:U615,2,) -> 0 | E5: =VLOOKUP(D5,'Sheet A'!D5:V615,2,) -> 1 | F5: =VLOOKUP(E5,'Sheet A'!E5:W615,2,) -> 3 | G5: =VLOOKUP(F5,'Sheet A'!F5:X615,2,) -> Night | H5: =VLOOKUP(G5,'Sheet A'!G5:Y615,2,) -> FALSE | I5: =VLOOKUP(H5,'Sheet A'!H5:Z615,2,) -> 6 | ... S5: =VLOOKUP(R5,'Sheet A'!R5:AJ615,2,) -> 13
A6: 5 | B6: =VLOOKUP(A6,'Sheet A'!A6:S616,2,) -> 40544 | C6: =VLOOKUP(B6,'Sheet A'!B6:T616,2,) -> 1 | D6: =VLOOKUP(C6,'Sheet A'!C6:U616,2,) -> 0 | E6: =VLOOKUP(D6,'Sheet A'!D6:V616,2,) -> 1 | F6: =VLOOKUP(E6,'Sheet A'!E6:W616,2,) -> 4 | G6: =VLOOKUP(F6,'Sheet A'!F6:X616,2,) -> Night | H6: =VLOOKUP(G6,'Sheet A'!G6:Y616,2,) -> FALSE | I6: =VLOOKUP(H6,'Sheet A'!H6:Z616,2,) -> 6 | ... S6: =VLOOKUP(R6,'Sheet A'!R6:AJ616,2,) -> 1
A7: 6 | B7: =VLOOKUP(A7,'Sheet A'!A7:S617,2,) -> 40544 | C7: =VLOOKUP(B7,'Sheet A'!B7:T617,2,) -> 1 | D7: =VLOOKUP(C7,'Sheet A'!C7:U617,2,) -> 0 | E7: =VLOOKUP(D7,'Sheet A'!D7:V617,2,) -> 1 | F7: =VLOOKUP(E7,'Sheet A'!E7:W617,2,) -> 5 | G7: =VLOOKUP(F7,'Sheet A'!F7:X617,2,) -> Morning | H7: =VLOOKUP(G7,'Sheet A'!G7:Y617,2,) -> FALSE | I7: =VLOOKUP(H7,'Sheet A'!H7:Z617,2,) -> 6 | ... S7: =VLOOKUP(R7,'Sheet A'!R7:AJ617,2,) -> 1
A8: 7 | B8: =VLOOKUP(A8,'Sheet A'!A8:S618,2,) -> 40544 | C8: =VLOOKUP(B8,'Sheet A'!B8:T618,2,) -> 1 | D8: =VLOOKUP(C8,'Sheet A'!C8:U618,2,) -> 0 | E8: =VLOOKUP(D8,'Sheet A'!D8:V618,2,) -> 1 | F8: =VLOOKUP(E8,'Sheet A'!E8:W618,2,) -> 6 | G8: =VLOOKUP(F8,'Sheet A'!F8:X618,2,) -> Morning | H8: =VLOOKUP(G8,'Sheet A'!G8:Y618,2,) -> FALSE | I8: =VLOOKUP(H8,'Sheet A'!H8:Z618,2,) -> 6 | ... S8: =VLOOKUP(R8,'Sheet A'!R8:AJ618,2,) -> 2
A9: 8 | B9: =VLOOKUP(A9,'Sheet A'!A9:S619,2,) -> 40544 | C9: =VLOOKUP(B9,'Sheet A'!B9:T619,2,) -> 1 | D9: =VLOOKUP(C9,'Sheet A'!C9:U619,2,) -> 0 | E9: =VLOOKUP(D9,'Sheet A'!D9:V619,2,) -> 1 | F9: =VLOOKUP(E9,'Sheet A'!E9:W619,2,) -> 7 | G9: =VLOOKUP(F9,'Sheet A'!F9:X619,2,) -> Morning | H9: =VLOOKUP(G9,'Sheet A'!G9:Y619,2,) -> FALSE | I9: =VLOOKUP(H9,'Sheet A'!H9:Z619,2,) -> 6 | ... S9: =VLOOKUP(R9,'Sheet A'!R9:AJ619,2,) -> 3
A10: 9 | B10: =VLOOKUP(A10,'Sheet A'!A10:S620,2,) -> 40544 | C10: =VLOOKUP(B10,'Sheet A'!B10:T620,2,) -> 1 | D10: =VLOOKUP(C10,'Sheet A'!C10:U620,2,) -> 0 | E10: =VLOOKUP(D10,'Sheet A'!D10:V620,2,) -> 1 | F10: =VLOOKUP(E10,'Sheet A'!E10:W620,2,) -> 8 | G10: =VLOOKUP(F10,'Sheet A'!F10:X620,2,) -> Morning | H10: =VLOOKUP(G10,'Sheet A'!G10:Y620,2,) -> FALSE | I10: =VLOOKUP(H10,'Sheet A'!H10:Z620,2,) -> 6 | ... S10: =VLOOKUP(R10,'Sheet A'!R10:AJ620,2,) -> 8
A11: 10 | B11: =VLOOKUP(A11,'Sheet A'!A11:S621,2,) -> 40544 | C11: =VLOOKUP(B11,'Sheet A'!B11:T621,2,) -> 1 | D11: =VLOOKUP(C11,'Sheet A'!C11:U621,2,) -> 0 | E11: =VLOOKUP(D11,'Sheet A'!D11:V621,2,) -> 1 | F11: =VLOOKUP(E11,'Sheet A'!E11:W621,2,) -> 9 | G11: =VLOOKUP(F11,'Sheet A'!F11:X621,2,) -> Morning | H11: =VLOOKUP(G11,'Sheet A'!G11:Y621,2,) -> FALSE | I11: =VLOOKUP(H11,'Sheet A'!H11:Z621,2,) -> 6 | ... S11: =VLOOKUP(R11,'Sheet A'!R11:AJ621,2,) -> 14
A12: 11 | B12: =VLOOKUP(A12,'Sheet A'!A12:S622,2,) -> 40544 | C12: =VLOOKUP(B12,'Sheet A'!B12:T622,2,) -> 1 | D12: =VLOOKUP(C12,'Sheet A'!C12:U622,2,) -> 0 | E12: =VLOOKUP(D12,'Sheet A'!D12:V622,2,) -> 1 | F12: =VLOOKUP(E12,'Sheet A'!E12:W622,2,) -> 10 | G12: =VLOOKUP(F12,'Sheet A'!F12:X622,2,) -> Morning | H12: =VLOOKUP(G12,'Sheet A'!G12:Y622,2,) -> FALSE | I12: =VLOOKUP(H12,'Sheet A'!H12:Z622,2,) -> 6 | ... S12: =VLOOKUP(R12,'Sheet A'!R12:AJ622,2,) -> 36
A13: 12 | B13: =VLOOKUP(A13,'Sheet A'!A13:S623,2,) -> 40544 | C13: =VLOOKUP(B13,'Sheet A'!B13:T623,2,) -> 1 | D13: =VLOOKUP(C13,'Sheet A'!C13:U623,2,) -> 0 | E13: =VLOOKUP(D13,'Sheet A'!D13:V623,2,) -> 1 | F13: =VLOOKUP(E13,'Sheet A'!E13:W623,2,) -> 11 | G13: =VLOOKUP(F13,'Sheet A'!F13:X623,2,) -> Morning | H13: =VLOOKUP(G13,'Sheet A'!G13:Y623,2,) -> FALSE | I13: =VLOOKUP(H13,'Sheet A'!H13:Z623,2,) -> 6 | ... S13: =VLOOKUP(R13,'Sheet A'!R13:AJ623,2,) -> 56
... A611: 610 | B611: =VLOOKUP(A611,'Sheet A'!A611:S1221,2,) -> 40571 | C611: =VLOOKUP(B611,'Sheet A'!B611:T1221,2,) -> 1 | D611: =VLOOKUP(C611,'Sheet A'!C611:U1221,2,) -> 0 | E611: =VLOOKUP(D611,'Sheet A'!D611:V1221,2,) -> 1 | F611: =VLOOKUP(E611,'Sheet A'!E611:W1221,2,) -> 15 | G611: =VLOOKUP(F611,'Sheet A'!F611:X1221,2,) -> AfterNoon | H611: =VLOOKUP(G611,'Sheet A'!G611:Y1221,2,) -> FALSE | I611: =VLOOKUP(H611,'Sheet A'!H611:Z1221,2,) -> 5 | ... S611: =VLOOKUP(R611,'Sheet A'!R611:AJ1221,2,) -> 41
A612: 611 | B612: =VLOOKUP(A612,'Dataset-3'!A3:S392,2,) -> 40571 | C612: =VLOOKUP(B612,'Dataset-3'!B3:T392,2,) -> 1 | D612: =VLOOKUP(C612,'Dataset-3'!C3:U392,2,) -> 0 | E612: =VLOOKUP(D612,'Dataset-3'!D3:V392,2,) -> 1 | F612: =VLOOKUP(E612,'Dataset-3'!E3:W392,2,) -> 16 | G612: =VLOOKUP(F612,'Dataset-3'!F3:X392,2,) -> AfterNoon | H612: =VLOOKUP(G612,'Dataset-3'!G3:Y392,2,) -> FALSE | I612: =VLOOKUP(H612,'Dataset-3'!H3:Z392,2,) -> 5 | ... S612: =VLOOKUP(R612,'Dataset-3'!R3:AJ392,2,) -> 80
A613: 612 | B613: =VLOOKUP(A613,'Dataset-3'!A4:S393,2,) -> 40571 | C613: =VLOOKUP(B613,'Dataset-3'!B4:T393,2,) -> 1 | D613: =VLOOKUP(C613,'Dataset-3'!C4:U393,2,) -> 0 | E613: =VLOOKUP(D613,'Dataset-3'!D4:V393,2,) -> 1 | F613: =VLOOKUP(E613,'Dataset-3'!E4:W393,2,) -> 17 | G613: =VLOOKUP(F613,'Dataset-3'!F4:X393,2,) -> Evening | H613: =VLOOKUP(G613,'Dataset-3'!G4:Y393,2,) -> FALSE | I613: =VLOOKUP(H613,'Dataset-3'!H4:Z393,2,) -> 5 | ... S613: =VLOOKUP(R613,'Dataset-3'!R4:AJ393,2,) -> 149
A614: 613 | B614: =VLOOKUP(A614,'Dataset-3'!A5:S394,2,) -> 40571 | C614: =VLOOKUP(B614,'Dataset-3'!B5:T394,2,) -> 1 | D614: =VLOOKUP(C614,'Dataset-3'!C5:U394,2,) -> 0 | E614: =VLOOKUP(D614,'Dataset-3'!D5:V394,2,) -> 1 | F614: =VLOOKUP(E614,'Dataset-3'!E5:W394,2,) -> 18 | G614: =VLOOKUP(F614,'Dataset-3'!F5:X394,2,) -> Evening | H614: =VLOOKUP(G614,'Dataset-3'!G5:Y394,2,) -> FALSE | I614: =VLOOKUP(H614,'Dataset-3'!H5:Z394,2,) -> 5 | ... S614: =VLOOKUP(R614,'Dataset-3'!R5:AJ394,2,) -> 109
A615: 614 | B615: =VLOOKUP(A615,'Dataset-3'!A6:S395,2,) -> 40571 | C615: =VLOOKUP(B615,'Dataset-3'!B6:T395,2,) -> 1 | D615: =VLOOKUP(C615,'Dataset-3'!C6:U395,2,) -> 0 | E615: =VLOOKUP(D615,'Dataset-3'!D6:V395,2,) -> 1 | F615: =VLOOKUP(E615,'Dataset-3'!E6:W395,2,) -> 19 | G615: =VLOOKUP(F615,'Dataset-3'!F6:X395,2,) -> Evening | H615: =VLOOKUP(G615,'Dataset-3'!G6:Y395,2,) -> FALSE | I615: =VLOOKUP(H615,'Dataset-3'!H6:Z395,2,) -> 5 | ... S615: =VLOOKUP(R615,'Dataset-3'!R6:AJ395,2,) -> 89
A616: 615 | B616: =VLOOKUP(A616,'Dataset-3'!A7:S396,2,) -> 40571 | C616: =VLOOKUP(B616,'Dataset-3'!B7:T396,2,) -> 1 | D616: =VLOOKUP(C616,'Dataset-3'!C7:U396,2,) -> 0 | E616: =VLOOKUP(D616,'Dataset-3'!D7:V396,2,) -> 1 | F616: =VLOOKUP(E616,'Dataset-3'!E7:W396,2,) -> 20 | G616: =VLOOKUP(F616,'Dataset-3'!F7:X396,2,) -> Night | H616: =VLOOKUP(G616,'Dataset-3'!G7:Y396,2,) -> FALSE | I616: =VLOOKUP(H616,'Dataset-3'!H7:Z396,2,) -> 5 | ... S616: =VLOOKUP(R616,'Dataset-3'!R7:AJ396,2,) -> 62
A617: 616 | B617: =VLOOKUP(A617,'Dataset-3'!A8:S397,2,) -> 40571 | C617: =VLOOKUP(B617,'Dataset-3'!B8:T397,2,) -> 1 | D617: =VLOOKUP(C617,'Dataset-3'!C8:U397,2,) -> 0 | E617: =VLOOKUP(D617,'Dataset-3'!D8:V397,2,) -> 1 | F617: =VLOOKUP(E617,'Dataset-3'!E8:W397,2,) -> 21 | G617: =VLOOKUP(F617,'Dataset-3'!F8:X397,2,) -> Night | H617: =VLOOKUP(G617,'Dataset-3'!G8:Y397,2,) -> FALSE | I617: =VLOOKUP(H617,'Dataset-3'!H8:Z397,2,) -> 5 | ... S617: =VLOOKUP(R617,'Dataset-3'!R8:AJ397,2,) -> 58
A618: 617 | B618: =VLOOKUP(A618,'Dataset-3'!A9:S398,2,) -> 40571 | C618: =VLOOKUP(B618,'Dataset-3'!B9:T398,2,) -> 1 | D618: =VLOOKUP(C618,'Dataset-3'!C9:U398,2,) -> 0 | E618: =VLOOKUP(D618,'Dataset-3'!D9:V398,2,) -> 1 | F618: =VLOOKUP(E618,'Dataset-3'!E9:W398,2,) -> 22 | G618: =VLOOKUP(F618,'Dataset-3'!F9:X398,2,) -> Night | H618: =VLOOKUP(G618,'Dataset-3'!G9:Y398,2,) -> FALSE | I618: =VLOOKUP(H618,'Dataset-3'!H9:Z398,2,) -> 5 | ... S618: =VLOOKUP(R618,'Dataset-3'!R9:AJ398,2,) -> 26
A619: 618 | B619: =VLOOKUP(A619,'Dataset-3'!A10:S399,2,) -> 40571 | C619: =VLOOKUP(B619,'Dataset-3'!B10:T399,2,) -> 1 | D619: =VLOOKUP(C619,'Dataset-3'!C10:U399,2,) -> 0 | E619: =VLOOKUP(D619,'Dataset-3'!D10:V399,2,) -> 1 | F619: =VLOOKUP(E619,'Dataset-3'!E10:W399,2,) -> 23 | G619: =VLOOKUP(F619,'Dataset-3'!F10:X399,2,) -> Night | H619: =VLOOKUP(G619,'Dataset-3'!G10:Y399,2,) -> FALSE | I619: =VLOOKUP(H619,'Dataset-3'!H10:Z399,2,) -> 5 | ... S619: =VLOOKUP(R619,'Dataset-3'!R10:AJ399,2,) -> 23
A620: 619 | B620: =VLOOKUP(A620,'Dataset-3'!A11:S400,2,) -> 40572 | C620: =VLOOKUP(B620,'Dataset-3'!B11:T400,2,) -> 1 | D620: =VLOOKUP(C620,'Dataset-3'!C11:U400,2,) -> 0 | E620: =VLOOKUP(D620,'Dataset-3'!D11:V400,2,) -> 1 | F620: =VLOOKUP(E620,'Dataset-3'!E11:W400,2,) -> 0 | G620: =VLOOKUP(F620,'Dataset-3'!F11:X400,2,) -> Night | H620: =VLOOKUP(G620,'Dataset-3'!G11:Y400,2,) -> FALSE | I620: =VLOOKUP(H620,'Dataset-3'!H11:Z400,2,) -> 6 | ... S620: =VLOOKUP(R620,'Dataset-3'!R11:AJ400,2,) -> 28
A621: 620 | B621: =VLOOKUP(A621,'Dataset-3'!A12:S401,2,) -> 40572 | C621: =VLOOKUP(B621,'Dataset-3'!B12:T401,2,) -> 1 | D621: =VLOOKUP(C621,'Dataset-3'!C12:U401,2,) -> 0 | E621: =VLOOKUP(D621,'Dataset-3'!D12:V401,2,) -> 1 | F621: =VLOOKUP(E621,'Dataset-3'!E12:W401,2,) -> 1 | G621: =VLOOKUP(F621,'Dataset-3'!F12:X401,2,) -> Night | H621: =VLOOKUP(G621,'Dataset-3'!G12:Y401,2,) -> FALSE | I621: =VLOOKUP(H621,'Dataset-3'!H12:Z401,2,) -> 6 | ... S621: =VLOOKUP(R621,'Dataset-3'!R12:AJ401,2,) -> 20
A622: 621 | B622: =VLOOKUP(A622,'Dataset-3'!A13:S402,2,) -> 40572 | C622: =VLOOKUP(B622,'Dataset-3'!B13:T402,2,) -> 1 | D622: =VLOOKUP(C622,'Dataset-3'!C13:U402,2,) -> 0 | E622: =VLOOKUP(D622,'Dataset-3'!D13:V402,2,) -> 1 | F622: =VLOOKUP(E622,'Dataset-3'!E13:W402,2,) -> 2 | G622: =VLOOKUP(F622,'Dataset-3'!F13:X402,2,) -> Night | H622: =VLOOKUP(G622,'Dataset-3'!G13:Y402,2,) -> FALSE | I622: =VLOOKUP(H622,'Dataset-3'!H13:Z402,2,) -> 6 | ... S622: =VLOOKUP(R622,'Dataset-3'!R13:AJ402,2,) -> 15
A623: 622 | B623: =VLOOKUP(A623,'Dataset-3'!A14:S403,2,) -> 40572 | C623: =VLOOKUP(B623,'Dataset-3'!B14:T403,2,) -> 1 | D623: =VLOOKUP(C623,'Dataset-3'!C14:U403,2,) -> 0 | E623: =VLOOKUP(D623,'Dataset-3'!D14:V403,2,) -> 1 | F623: =VLOOKUP(E623,'Dataset-3'!E14:W403,2,) -> 3 | G623: =VLOOKUP(F623,'Dataset-3'!F14:X403,2,) -> Night | H623: =VLOOKUP(G623,'Dataset-3'!G14:Y403,2,) -> FALSE | I623: =VLOOKUP(H623,'Dataset-3'!H14:Z403,2,) -> 6 | ... S623: =VLOOKUP(R623,'Dataset-3'!R14:AJ403,2,) -> 8
... A1001: 1000 | B1001: =VLOOKUP(A1001,'Dataset-3'!A392:S781,2,) -> 40588 | C1001: =VLOOKUP(B1001,'Dataset-3'!B392:T781,2,) -> 1 | D1001: =VLOOKUP(C1001,'Dataset-3'!C392:U781,2,) -> 0 | E1001: =VLOOKUP(D1001,'Dataset-3'!D392:V781,2,) -> 2 | F1001: =VLOOKUP(E1001,'Dataset-3'!E392:W781,2,) -> 7 | G1001: =VLOOKUP(F1001,'Dataset-3'!F392:X781,2,) -> Morning | H1001: =VLOOKUP(G1001,'Dataset-3'!G392:Y781,2,) -> FALSE | I1001: =VLOOKUP(H1001,'Dataset-3'!H392:Z781,2,) -> 1 | ... S1001: =VLOOKUP(R1001,'Dataset-3'!R392:AJ781,2,) -> 98
R1003: Average of Registrarion
R1004: =AVERAGE(R2:R1001) -> 53.383

Sheet Pivot Table
A3: Total Count
A4: Sum of Cnt
A5: 58304
A7: Total Registered
A8: 53383
A10: Total Casual
A11: 4921
A13: Total Customers Get Registerd
A14: Sum of Cnt | B14: Sum of Registered
A15: 58304 | B15: 53383
A17: Customer Demand On Different type of Weather
A18: Row Labels | B18: Sum of Casual | C18: Sum of Registered | D18: Sum of Cnt
A19: Cloudy | B19: 1894 | C19: 19949 | D19: 21843
A20: Sunny | B20: 1540 | C20: 6729 | D20: 8269
A21: Rainy | B21: 1343 | C21: 24070 | D21: 25413
A22: Stromy | B22: 144 | C22: 2635 | D22: 2779
A23: Grand Total | B23: 4921 | C23: 53383 | D23: 58304
A34: No. Of Customer Visits On Weekdays
A35: Row Labels | B35: Sum of Cnt | C35: Sum of Registered | D35: Sum of Casual
A36: Sunday | B36: 8450 | C36: 7916 | D36: 534
A37: Monday | B37: 8383 | C37: 7926 | D37: 457
A38: Tuesday | B38: 8049 | C38: 7705 | D38: 344
A39: Wednesday | B39: 8458 | C39: 8126 | D39: 332
A40: Friday | B40: 7748 | C40: 6523 | D40: 1225
A41: Saturday | B41: 8121 | C41: 6644 | D41: 1477
A42: Thusday | B42: 9095 | C42: 8543 | D42: 552
A43: Grand Total | B43: 58304 | C43: 53383 | D43: 4921
A51: No. Of Customers Visited On Particular Date
A52: Row Labels | B52: Sum of Cnt
A53: 40544 | B53: 985
A54: 40545 | B54: 801
A55: 40546 | B55: 1349
A56: 40547 | B56: 1562
A57: 40548 | B57: 1600
A58: 40549 | B58: 1606
A59: 40550 | B59: 1510
A60: 40551 | B60: 959
A61: 40552 | B61: 822
A62: 40553 | B62: 1321
A63: 40554 | B63: 1263
...

Sheet Dashboard

Sheet Sheet2
A2: Customer Demand On Differ Weather
A3: Row Labels | B3: Sum of Casual | C3: Sum of Registered | D3: Sum of Cnt
A4: Cloudy | B4: 1894 | C4: 19949 | D4: 21843
A5: Sunny | B5: 1540 | C5: 6729 | D5: 8269
A6: Rainy | B6: 1343 | C6: 24070 | D6: 25413
A7: Stromy | B7: 144 | C7: 2635 | D7: 2779
A8: Grand Total | B8: 4921 | C8: 53383 | D8: 58304

Sheet Sheet5
A1: Instant | B1: Holiday | C1: Dteday | D1: Season | E1: Yr | F1: Mnth | G1: Hr | H1: Weekday | I1: Weathersit | J1: Temp | K1: N Atemp | L1: Hum | M1: Windspeed | N1: Casual | O1: Registered | P1: Cnt
A2: 1 | B2: FALSE | C2: 40544 | D2: 1 | E2: 0 | F2: 1 | G2: 0 | H2: 6 | I2: 1 | J2: 0.24 | K2: 0.2879 | L2: 0.81 | M2: 0 | N2: 3 | O2: 13 | P2: 16
A3: 2 | B3: FALSE | C3: 40544 | D3: 1 | E3: 0 | F3: 1 | G3: 1 | H3: 6 | I3: 1 | J3: 0.22 | K3: 0.2727 | L3: 0.8 | M3: 0 | N3: 8 | O3: 32 | P3: 40
A4: 3 | B4: FALSE | C4: 40544 | D4: 1 | E4: 0 | F4: 1 | G4: 2 | H4: 6 | I4: 1 | J4: 0.22 | K4: 0.2727 | L4: 0.8 | M4: 0 | N4: 5 | O4: 27 | P4: 32
A5: 4 | B5: FALSE | C5: 40544 | D5: 1 | E5: 0 | F5: 1 | G5: 3 | H5: 6 | I5: 1 | J5: 0.24 | K5: 0.2879 | L5: 0.75 | M5: 0 | N5: 3 | O5: 10 | P5: 13
A6: 5 | B6: FALSE | C6: 40544 | D6: 1 | E6: 0 | F6: 1 | G6: 4 | H6: 6 | I6: 1 | J6: 0.24 | K6: 0.2879 | L6: 0.75 | M6: 0 | N6: 0 | O6: 1 | P6: 1
A7: 6 | B7: FALSE | C7: 40544 | D7: 1 | E7: 0 | F7: 1 | G7: 5 | H7: 6 | I7: 2 | J7: 0.24 | K7: 0.2576 | L7: 0.75 | M7: 0.0896 | N7: 0 | O7: 1 | P7: 1
A8: 7 | B8: FALSE | C8: 40544 | D8: 1 | E8: 0 | F8: 1 | G8: 6 | H8: 6 | I8: 1 | J8: 0.22 | K8: 0.2727 | L8: 0.8 | M8: 0 | N8: 2 | O8: 0 | P8: 2
A9: 8 | B9: FALSE | C9: 40544 | D9: 1 | E9: 0 | F9: 1 | G9: 7 | H9: 6 | I9: 1 | J9: 0.2 | K9: 0.2576 | L9: 0.86 | M9: 0 | N9: 1 | O9: 2 | P9: 3
A10: 9 | B10: FALSE | C10: 40544 | D10: 1 | E10: 0 | F10: 1 | G10: 8 | H10: 6 | I10: 1 | J10: 0.24 | K10: 0.30305 | L10: 0.75 | M10: 0 | N10: 1 | O10: 7 | P10: 8
A11: 10 | B11: FALSE | C11: 40544 | D11: 1 | E11: 0 | F11: 1 | G11: 9 | H11: 6 | I11: 1 | J11: 0.32 | K11: 0.3485 | L11: 0.76 | M11: 0 | N11: 8 | O11: 6 | P11: 14
A12: 11 | B12: FALSE | C12: 40544 | D12: 1 | E12: 0 | F12: 1 | G12: 10 | H12: 6 | I12: 1 | J12: 0.38 | K12: 0.3939 | L12: 0.76 | M12: 0.2537 | N12: 12 | O12: 24 | P12: 36
A13: 12 | B13: FALSE | C13: 40544 | D13: 1 | E13: 0 | F13: 1 | G13: 11 | H13: 6 | I13: 1 | J13: 0.36 | K13: 0.3333 | L13: 0.81 | M13: 0.2836 | N13: 26 | O13: 30 | P13: 56
... A1001: 1000 | B1001: FALSE | C1001: 40588 | D1001: 1 | E1001: 0 | F1001: 2 | G1001: 7 | H1001: 1 | I1001: 1 | J1001: 0.34 | K1001: 0.303 | L1001: 0.46 | M1001: 0.2985 | N1001: 2 | O1001: 96 | P1001: 98

Sheet dash que
A1: cnt me se register kitna hua count kitna hua
A2: kitne hrs pe kitne count aae
A3: weekdays pe kitne count aae
A4: weekdays pe kitne hr pe kitne count aae aur unme se kitne registerhue aur uss samay temp. kya tha
A5: user demand by time
